Workbook

Sheet A̳ssets
B3: Paleta de Cores
B5: # 9BC848 | C5: Xbox Color | E5: # E8E6E9 | F5: negative zone
B6: # 22C55E | C6: Xbox Color
B7: # 2AE6B1 | C7: Menus
B8: # 5BF6A8 | C8: Menus
B12: Logos | J12: ícones

Sheet B̳ases
A1: Subscriber ID | B1: Name | C1: Plan | D1: Start Date | E1: Auto Renewal | F1: Subscription Price | G1: Subscription Type | H1: EA Play Season Pass | I1: EA Play Season Pass Price | J1: Minecraft Season Pass | K1: Minecraft Season Pass Price | L1: Coupon Value | M1: Total Value
A2: 3231 | B2: João Silva | C2: Ultimate | D2: 45292 | E2: Yes | F2: 15 | G2: Monthly | H2: Yes | I2: 30 | J2: Yes | K2: 20 | L2: 5 | M2: 60
A3: 3232 | B3: Maria Oliveira | C3: Core | D3: 45306 | E3: No | F3: 5 | G3: Annual | H3: No | I3: - | J3: No | K3: 0 | L3: 0 | M3: 5
A4: 3233 | B4: Lucas Fernandes | C4: Standard | D4: 45332 | E4: Yes | F4: 10 | G4: Quarterly | H4: No | I4: - | J4: Yes | K4: 20 | L4: 10 | M4: 20
A5: 3234 | B5: Ana Souza | C5: Ultimate | D5: 45342 | E5: No | F5: 15 | G5: Monthly | H5: Yes | I5: 30 | J5: Yes | K5: 20 | L5: 3 | M5: 62
A6: 3235 | B6: Pedro Gonçalves | C6: Core | D6: 45356 | E6: Yes | F6: 5 | G6: Monthly | H6: No | I6: - | J6: No | K6: 0 | L6: 1 | M6: 4
A7: 3236 | B7: Felipe Costa | C7: Standard | D7: 45353 | E7: No | F7: 10 | G7: Monthly | H7: No | I7: - | J7: Yes | K7: 20 | L7: 2 | M7: 28
A8: 3237 | B8: Camila Ribeiro | C8: Ultimate | D8: 45354 | E8: Yes | F8: 15 | G8: Quarterly | H8: Yes | I8: 30 | J8: Yes | K8: 20 | L8: 10 | M8: 55
A9: 3238 | B9: André Mendes | C9: Core | D9: 45355 | E9: Yes | F9: 5 | G9: Annual | H9: No | I9: - | J9: No | K9: 0 | L9: 0 | M9: 5
A10: 3239 | B10: Sofia Almeida | C10: Ultimate | D10: 45356 | E10: No | F10: 15 | G10: Monthly | H10: Yes | I10: 30 | J10: Yes | K10: 20 | L10: 5 | M10: 60
A11: 3240 | B11: Bruno Martins | C11: Standard | D11: 45357 | E11: Yes | F11: 10 | G11: Quarterly | H11: No | I11: - | J11: Yes | K11: 20 | L11: 15 | M11: 15
A12: 3241 | B12: Rita Castro | C12: Core | D12: 45358 | E12: No | F12: 5 | G12: Monthly | H12: No | I12: - | J12: No | K12: 0 | L12: 1 | M12: 4
A13: 3242 | B13: Marco Túlio | C13: Ultimate | D13: 45359 | E13: Yes | F13: 15 | G13: Annual | H13: Yes | I13: 30 | J13: Yes | K13: 20 | L13: 20 | M13: 45
A14: 3243 | B14: Lívia Silveira | C14: Standard | D14: 45360 | E14: No | F14: 10 | G14: Monthly | H14: No | I14: - | J14: Yes | K14: 20 | L14: 10 | M14: 20
A15: 3244 | B15: Diogo Sousa | C15: Core | D15: 45361 | E15: Yes | F15: 5 | G15: Quarterly | H15: No | I15: - | J15: No | K15: 0 | L15: 0 | M15: 5
A16: 3245 | B16: Fernanda Lima | C16: Ultimate | D16: 45362 | E16: No | F16: 15 | G16: Monthly | H16: Yes | I16: 30 | J16: Yes | K16: 20 | L16: 8 | M16: 57
A17: 3246 | B17: Caio Pereira | C17: Standard | D17: 45363 | E17: Yes | F17: 10 | G17: Annual | H17: No | I17: - | J17: Yes | K17: 20 | L17: 12 | M17: 18
A18: 3247 | B18: Beatriz Gomes | C18: Core | D18: 45364 | E18: No | F18: 5 | G18: Monthly | H18: No | I18: - | J18: No | K18: 0 | L18: 2 | M18: 3
A19: 3248 | B19: Cesar Oliveira | C19: Ultimate | D19: 45365 | E19: Yes | F19: 15 | G19: Quarterly | H19: Yes | I19: 30 | J19: Yes | K19: 20 | L19: 7 | M19: 58
A20: 3249 | B20: Débora Machado | C20: Standard | D20: 45366 | E20: No | F20: 10 | G20: Monthly | H20: No | I20: - | J20: Yes | K20: 20 | L20: 5 | M20: 25
A21: 3250 | B21: Eduardo Vargas | C21: Core | D21: 45367 | E21: Yes | F21: 5 | G21: Annual | H21: No | I21: - | J21: No | K21: 0 | L21: 0 | M21: 5
A22: 3251 | B22: Gabriela Santos | C22: Ultimate | D22: 45368 | E22: No | F22: 15 | G22: Monthly | H22: Yes | I22: 30 | J22: Yes | K22: 20 | L22: 3 | M22: 62
A23: 3252 | B23: Henrique Dias | C23: Standard | D23: 45369 | E23: Yes | F23: 10 | G23: Quarterly | H23: No | I23: - | J23: Yes | K23: 20 | L23: 15 | M23: 15
A24: 3253 | B24: Isabela Moreira | C24: Core | D24: 45370 | E24: No | F24: 5 | G24: Monthly | H24: No | I24: - | J24: No | K24: 0 | L24: 1 | M24: 4
A25: 3254 | B25: Joaquim Barbosa | C25: Ultimate | D25: 45371 | E25: Yes | F25: 15 | G25: Annual | H25: Yes | I25: 30 | J25: Yes | K25: 20 | L25: 20 | M25: 45
A26: 3255 | B26: Lara Rocha | C26: Standard | D26: 45372 | E26: No | F26: 10 | G26: Monthly | H26: No | I26: - | J26: Yes | K26: 20 | L26: 10 | M26: 20
A27: 3256 | B27: Matheus Silva | C27: Core | D27: 45373 | E27: Yes | F27: 5 | G27: Quarterly | H27: No | I27: - | J27: No | K27: 0 | L27: 0 | M27: 5
A28: 3257 | B28: Nicole Costa | C28: Ultimate | D28: 45374 | E28: No | F28: 15 | G28: Monthly | H28: Yes | I28: 30 | J28: Yes | K28: 20 | L28: 5 | M28: 60
A29: 3258 | B29: Otávio Mendonça | C29: Standard | D29: 45375 | E29: Yes | F29: 10 | G29: Annual | H29: No | I29: - | J29: Yes | K29: 20 | L29: 15 | M29: 15
A30: 3259 | B30: Paula Ferreira | C30: Core | D30: 45376 | E30: No | F30: 5 | G30: Monthly | H30: No | I30: - | J30: No | K30: 0 | L30: 1 | M30: 4
A31: 3260 | B31: Raquel Alves | C31: Ultimate | D31: 45377 | E31: Yes | F31: 15 | G31: Quarterly | H31: Yes | I31: 30 | J31: Yes | K31: 20 | L31: 7 | M31: 58
A32: 3261 | B32: Samuel Pires | C32: Standard | D32: 45378 | E32: No | F32: 10 | G32: Monthly | H32: No | I32: - | J32: Yes | K32: 20 | L32: 10 | M32: 20
A33: 3262 | B33: Tânia Barros | C33: Core | D33: 45379 | E33: Yes | F33: 5 | G33: Annual | H33: No | I33: - | J33: No | K33: 0 | L33: 0 | M33: 5
A34: 3263 | B34: Vinicius Lima | C34: Ultimate | D34: 45380 | E34: No | F34: 15 | G34: Monthly | H34: Yes | I34: 30 | J34: Yes | K34: 20 | L34: 3 | M34: 62
A35: 3264 | B35: Yasmin Teixeira | C35: Standard | D35: 45381 | E35: Yes | F35: 10 | G35: Quarterly | H35: No | I35: - | J35: Yes | K35: 20 | L35: 15 | M35: 15
A36: 3265 | B36: Zé Carlos | C36: Core | D36: 45382 | E36: No | F36: 5 | G36: Monthly | H36: No | I36: - | J36: No | K36: 0 | L36: 1 | M36: 4
A37: 3266 | B37: Amanda Nogueira | C37: Core | D37: 45383 | E37: Yes | F37: 5 | G37: Monthly | H37: No | I37: - | J37: No | K37: 0 | L37: 0 | M37: 5
A38: 3267 | B38: Bruno Cavalheiro | C38: Ultimate | D38: 45384 | E38: No | F38: 15 | G38: Quarterly | H38: Yes | I38: 30 | J38: Yes | K38: 20 | L38: 7 | M38: 58
A39: 3268 | B39: Carla Dias | C39: Standard | D39: 45385 | E39: Yes | F39: 10 | G39: Annual | H39: No | I39: - | J39: Yes | K39: 20 | L39: 10 | M39: 20
A40: 3269 | B40: Diego Fontes | C40: Core | D40: 45386 | E40: No | F40: 5 | G40: Quarterly | H40: No | I40: - | J40: No | K40: 0 | L40: 1 | M40: 4
...

Sheet C̳álculos
B2: Cálculos — tabelas de apoio ao Dashboard
B4: 1. Parâmetro do filtro (vem da aba Dashboard)
B5: Filtro selecionado | C5: =D̳ashboard!$D$5 -> Quarterly
B6: Critério usado nas fórmulas ("*" = todos) | C6: =IF(C5="Todos","*",C5) -> Quarterly
B8: 2. KPIs — respondem ao filtro
B9: Métrica | C9: Valor | D9: Lógica
B10: Total R$ — EA Play Season Pass | C10: =SUMIFS(B̳ases!$I$2:$I$5000,B̳ases!$H$2:$H$5000,"Yes",B̳ases!$G$2:$G$5000,$C$6) -> 990 | D10: SOMASES(Preço EA; EA="Yes"; Tipo=critério)
B11: Total R$ — Minecraft Season Pass | C11: =SUMIFS(B̳ases!$K$2:$K$5000,B̳ases!$J$2:$J$5000,"Yes",B̳ases!$G$2:$G$5000,$C$6) -> 1140 | D11: SOMASES(Preço Minecraft; Minecraft="Yes"; Tipo=critério)
B12: Game Pass — Auto Renewal YES (qtd) | C12: =COUNTIFS(B̳ases!$E$2:$E$5000,"Yes",B̳ases!$G$2:$G$5000,$C$6) -> 60 | D12: CONT.SES(Auto Renewal="Yes"; Tipo=critério)
B13: Game Pass — Auto Renewal NO (qtd) | C13: =COUNTIFS(B̳ases!$E$2:$E$5000,"No",B̳ases!$G$2:$G$5000,$C$6) -> 25 | D13: CONT.SES(Auto Renewal="No"; Tipo=critério)
B14: Total de assinantes no filtro | C14: =COUNTIFS(B̳ases!$G$2:$G$5000,$C$6) -> 85 | D14: CONT.SES(Tipo=critério)
B15: % Auto Renewal YES | C15: =IFERROR(C12/C14,0) -> 0.70588235
B16: % Auto Renewal NO | C16: =IFERROR(C13/C14,0) -> 0.29411765
B18: 3. Resumo por tipo de faturamento — sem filtro
B19: Subscription Type | C19: EA Play (R$) | D19: Minecraft (R$) | E19: Auto Renewal YES | F19: Auto Renewal NO | G19: Total assinantes
B20: Annual | C20: =SUMIFS(B̳ases!$I$2:$I$5000,B̳ases!$H$2:$H$5000,"Yes",B̳ases!$G$2:$G$5000,$B20) -> 600 | D20: =SUMIFS(B̳ases!$K$2:$K$5000,B̳ases!$J$2:$J$5000,"Yes",B̳ases!$G$2:$G$5000,$B20) -> 940 | E20: =COUNTIFS(B̳ases!$E$2:$E$5000,"Yes",B̳ases!$G$2:$G$5000,$B20) -> 60 | F20: =COUNTIFS(B̳ases!$E$2:$E$5000,"No",B̳ases!$G$2:$G$5000,$B20) -> 11 | G20: =COUNTIFS(B̳ases!$G$2:$G$5000,$B20) -> 71
B21: Monthly | C21: =SUMIFS(B̳ases!$I$2:$I$5000,B̳ases!$H$2:$H$5000,"Yes",B̳ases!$G$2:$G$5000,$B21) -> 1350 | D21: =SUMIFS(B̳ases!$K$2:$K$5000,B̳ases!$J$2:$J$5000,"Yes",B̳ases!$G$2:$G$5000,$B21) -> 1800 | E21: =COUNTIFS(B̳ases!$E$2:$E$5000,"Yes",B̳ases!$G$2:$G$5000,$B21) -> 28 | F21: =COUNTIFS(B̳ases!$E$2:$E$5000,"No",B̳ases!$G$2:$G$5000,$B21) -> 111 | G21: =COUNTIFS(B̳ases!$G$2:$G$5000,$B21) -> 139
B22: Quarterly | C22: =SUMIFS(B̳ases!$I$2:$I$5000,B̳ases!$H$2:$H$5000,"Yes",B̳ases!$G$2:$G$5000,$B22) -> 990 | D22: =SUMIFS(B̳ases!$K$2:$K$5000,B̳ases!$J$2:$J$5000,"Yes",B̳ases!$G$2:$G$5000,$B22) -> 1140 | E22: =COUNTIFS(B̳ases!$E$2:$E$5000,"Yes",B̳ases!$G$2:$G$5000,$B22) -> 60 | F22: =COUNTIFS(B̳ases!$E$2:$E$5000,"No",B̳ases!$G$2:$G$5000,$B22) -> 25 | G22: =COUNTIFS(B̳ases!$G$2:$G$5000,$B22) -> 85
B23: Total | C23: =SUM(C20:C22) -> 2940 | D23: =SUM(D20:D22) -> 3880 | E23: =SUM(E20:E22) -> 148 | F23: =SUM(F20:F22) -> 147 | G23: =SUM(G20:G22) -> 295
B25: 4. Dados do gráfico (respondem ao filtro)
B26: Categoria | C26: Qtd
B27: Yes (renovação ativa) | C27: =C12 -> 60
B28: No (sem renovação) | C28: =C13 -> 25
B30: 5. Checagens de consistência
B31: Soma EA por tipo = soma da base | C31: =IF(ROUND(C23-SUM(B̳ases!$I$2:$I$5000),2)=0,"OK","VERIFICAR") -> OK
B32: Soma Minecraft por tipo = soma da base | C32: =IF(ROUND(D23-SUM(B̳ases!$K$2:$K$5000),2)=0,"OK","VERIFICAR") -> OK
B33: Total de assinantes = linhas da base | C33: =IF(G23=COUNTA(B̳ases!$A$2:$A$5000),"OK","VERIFICAR") -> OK
B35: Obs.: as fórmulas leem as linhas 2 a 5000 da base; novas linhas entram automaticamente.

Sheet D̳ashboard
B2: Xbox Game Pass | Dashboard de Assinaturas | J2: EA Play & Minecraft Season Pass
B5: Tipo de faturamento ▸ | D5: Quarterly | F5: ◂ clique na seta para filtrar | J5: Assinantes no filtro: | M5: =C̳álculos!$C$14 -> 85
B7: TOTAL R$ — EA PLAY SEASON PASS | E7: TOTAL R$ — MINECRAFT SEASON PASS | H7: GAME PASS — AUTO RENEWAL: YES | K7: GAME PASS — AUTO RENEWAL: NO
B8: =C̳álculos!$C$10 -> 990 | E8: =C̳álculos!$C$11 -> 1140 | H8: =C̳álculos!$C$12 -> 60 | K8: =C̳álculos!$C$13 -> 25
B10: Valor acumulado no filtro | E10: Valor acumulado no filtro | H10: =TEXT(C̳álculos!$C$15,"0.0%")&" dos assinantes no filtro" -> 71% dos assinantes no filtro | K10: =TEXT(C̳álculos!$C$16,"0.0%")&" dos assinantes no filtro" -> 29% dos assinantes no filtro
B12: Distribuição do Xbox Game Pass — Auto Renewal | H12: Detalhe por status
H13: Status | J13: Qtd | L13: % do total
H14: Yes — renovação ativa | J14: =C̳álculos!$C$12 -> 60 | L14: =C̳álculos!$C$15 -> 0.70588235
H15: No — sem renovação | J15: =C̳álculos!$C$13 -> 25 | L15: =C̳álculos!$C$16 -> 0.29411765
H16: Total | J16: =C̳álculos!$C$14 -> 85 | L16: =IF(C̳álculos!$C$14=0,0,1) -> 1
H19: Como usar
H20: • O filtro atualiza os cartões, o gráfico e a tabela de status.
H21: • Escolha "Todos" para ver o consolidado da base.
H22: • A tabela inferior é fixa e destaca a linha do tipo escolhido.
B26: Totais por tipo de faturamento (sem filtro)
B27: Subscription Type | D27: EA Play (R$) | F27: Minecraft (R$) | H27: Auto Renewal YES | J27: Auto Renewal NO | L27: Total assinantes
B28: =C̳álculos!B20 -> Annual | D28: =C̳álculos!C20 -> 600 | F28: =C̳álculos!D20 -> 940 | H28: =C̳álculos!E20 -> 60 | J28: =C̳álculos!F20 -> 11 | L28: =C̳álculos!G20 -> 71
D29: =C̳álculos!C21 -> 1350 | F29: =C̳álculos!D21 -> 1800 | H29: =C̳álculos!E21 -> 28 | J29: =C̳álculos!F21 -> 111 | L29: =C̳álculos!G21 -> 139
D30: =C̳álculos!C22 -> 990 | F30: =C̳álculos!D22 -> 1140 | H30: =C̳álculos!E22 -> 60 | J30: =C̳álculos!F22 -> 25 | L30: =C̳álculos!G22 -> 85
D31: =C̳álculos!C23 -> 2940 | F31: =C̳álculos!D23 -> 3880 | H31: =C̳álculos!E23 -> 148 | J31: =C̳álculos!F23 -> 147 | L31: =C̳álculos!G23 -> 295
B33: ="Fonte: aba base de dados ("&TEXT(COUNTA(B̳ases!$A$2:$A$5000),"#,##0")&" assinantes). Valores em R$ · atualiza automaticamente." -> Fonte: aba base de dados (295,0 assinantes). Valores em R$ · atualiza automaticamente.
